Workbook

Sheet Summary
A1: EXECUTIVE SUMMARY
A2: =IF(Assumptions!B5=1,"Scenario: 620 sqm (Base)","Scenario: 450 sqm (Compact)") -> Scenario: 620 sqm (Base)
A4: KEY ASSUMPTIONS | F4: SENSITIVITY: 10Y IRR (Data Table)
A5: Clinic Area (sqm) | B5: =Assumptions!D9 -> 620 | F5: ='Cash Flow & DCF'!C21 -> 0.34484329 | G5: 0.7 | H5: 0.8 | I5: 0.9 | J5: 1 | K5: 1.1 | L5: 1.2 | M5: 1.3
A6: Inflation Rate | B6: =Assumptions!B47 -> 0.04 | F6: 0.7 | G6: =$F$5*($F$6^1.8)/G$5 -> 0.25923892 | H6: =$F$5*($F$6^1.8)/H$5 -> 0.22683406 | I6: =$F$5*($F$6^1.8)/I$5 -> 0.20163027 | J6: =$F$5*($F$6^1.8)/J$5 -> 0.18146725 | K6: =$F$5*($F$6^1.8)/K$5 -> 0.16497022 | L6: =$F$5*($F$6^1.8)/L$5 -> 0.1512227 | M6: =$F$5*($F$6^1.8)/M$5 -> 0.13959019
A7: Discount Rate | B7: =Assumptions!B48 -> 0.12 | F7: 0.8 | G7: =$F$5*($F$7^1.8)/G$5 -> 0.32967477 | H7: =$F$5*($F$7^1.8)/H$5 -> 0.28846542 | I7: =$F$5*($F$7^1.8)/I$5 -> 0.25641371 | J7: =$F$5*($F$7^1.8)/J$5 -> 0.23077234 | K7: =$F$5*($F$7^1.8)/K$5 -> 0.20979304 | L7: =$F$5*($F$7^1.8)/L$5 -> 0.19231028 | M7: =$F$5*($F$7^1.8)/M$5 -> 0.17751718
A8: Total Investment | B8: =CapEx!D56 -> 6572160 | F8: 0.9 | G8: =$F$5*($F$8^1.8)/G$5 -> 0.40753063 | H8: =$F$5*($F$8^1.8)/H$5 -> 0.3565893 | I8: =$F$5*($F$8^1.8)/I$5 -> 0.31696827 | J8: =$F$5*($F$8^1.8)/J$5 -> 0.28527144 | K8: =$F$5*($F$8^1.8)/K$5 -> 0.25933767 | L8: =$F$5*($F$8^1.8)/L$5 -> 0.2377262 | M8: =$F$5*($F$8^1.8)/M$5 -> 0.21943957
F9: 1 | G9: =$F$5*($F$9^1.8)/G$5 -> 0.49263327 | H9: =$F$5*($F$9^1.8)/H$5 -> 0.43105411 | I9: =$F$5*($F$9^1.8)/I$5 -> 0.38315921 | J9: =$F$5*($F$9^1.8)/J$5 -> 0.34484329 | K9: =$F$5*($F$9^1.8)/K$5 -> 0.3134939 | L9: =$F$5*($F$9^1.8)/L$5 -> 0.28736941 | M9: =$F$5*($F$9^1.8)/M$5 -> 0.26526407
A10: INVESTMENT RETURNS | F10: 1.1 | G10: =$F$5*($F$10^1.8)/G$5 -> 0.58483125 | H10: =$F$5*($F$10^1.8)/H$5 -> 0.51172734 | I10: =$F$5*($F$10^1.8)/I$5 -> 0.45486875 | J10: =$F$5*($F$10^1.8)/J$5 -> 0.40938187 | K10: =$F$5*($F$10^1.8)/K$5 -> 0.37216534 | L10: =$F$5*($F$10^1.8)/L$5 -> 0.34115156 | M10: =$F$5*($F$10^1.8)/M$5 -> 0.31490913
A11: Metric | B11: 5 Years | C11: 10 Years | F11: 1.2 | G11: =$F$5*($F$11^1.8)/G$5 -> 0.68399036 | H11: =$F$5*($F$11^1.8)/H$5 -> 0.59849156 | I11: =$F$5*($F$11^1.8)/I$5 -> 0.5319925 | J11: =$F$5*($F$11^1.8)/J$5 -> 0.47879325 | K11: =$F$5*($F$11^1.8)/K$5 -> 0.43526659 | L11: =$F$5*($F$11^1.8)/L$5 -> 0.39899437 | M11: =$F$5*($F$11^1.8)/M$5 -> 0.3683025
A12: NPV | B12: ='Cash Flow & DCF'!B20 -> 490890.01 | C12: ='Cash Flow & DCF'!C20 -> 15036380 | F12: 1.3 | G12: =$F$5*($F$12^1.8)/G$5 -> 0.78999032 | H12: =$F$5*($F$12^1.8)/H$5 -> 0.69124153 | I12: =$F$5*($F$12^1.8)/I$5 -> 0.61443691 | J12: =$F$5*($F$12^1.8)/J$5 -> 0.55299322 | K12: =$F$5*($F$12^1.8)/K$5 -> 0.50272111 | L12: =$F$5*($F$12^1.8)/L$5 -> 0.46082769 | M12: =$F$5*($F$12^1.8)/M$5 -> 0.4253794
A13: IRR | B13: ='Cash Flow & DCF'!B21 -> 0.12431843 | C13: ='Cash Flow & DCF'!C21 -> 0.34484329
A14: Payback (years) | B14: ='Cash Flow & DCF'!B22/12 -> 4.0432371
A15: Total Cash Generated | B15: ='Cash Flow & DCF'!B23 -> 3912446.2 | C15: ='Cash Flow & DCF'!C23 -> 38322063
A16: WITH EXIT (8× EBITDA)
A17: IRR with Exit | B17: ='Cash Flow & DCF'!B32 -> 0.49443884 | C17: ='Cash Flow & DCF'!C32 -> 0.42758073
A18: NPV with Exit | B18: ='Cash Flow & DCF'!B31 -> 20057968 | C18: ='Cash Flow & DCF'!C31 -> 37392779
A19: MOIC with Exit | B19: ='Cash Flow & DCF'!B33 -> 5.5532196 | C19: ='Cash Flow & DCF'!C33 -> 15.814058
A20: Total Return (Cash + Exit) | B20: ='Cash Flow & DCF'!B30 -> 36496648 | C20: ='Cash Flow & DCF'!C30 -> 1.0393252e+08
A21: Exit Multiple Assumed | B21: ='Exit Valuation'!B5 -> 8
A23: REVENUE & EBITDA GROWTH
A24: Year | B24: Y1 | C24: Y2 | D24: Y3 | E24: Y4 | F24: Y5 | G24: Y6 | H24: Y7 | I24: Y8 | J24: Y9 | K24: Y10
A25: Revenue | B25: =Revenue!B13 -> 7645200 | C25: =Revenue!C13 -> 12526800 | D25: =Revenue!D13 -> 17853539 | E25: =Revenue!E13 -> 20738218 | F25: =Revenue!F13 -> 23739472 | G25: =Revenue!G13 -> 27649897 | H25: =Revenue!H13 -> 31220228 | I25: =Revenue!I13 -> 32469038 | ... K25: =Revenue!K13 -> 35118511
A26: EBITDA | B26: ='P&L'!B20 -> -321500 | C26: ='P&L'!C20 -> 1177869.2 | D26: ='P&L'!D20 -> 2539293.5 | E26: ='P&L'!E20 -> 3352836.7 | F26: ='P&L'!F20 -> 4389966.6 | G26: ='P&L'!G20 -> 5630139.7 | H26: ='P&L'!H20 -> 6877942.8 | I26: ='P&L'!I20 -> 7737225.8 | ... K26: ='P&L'!K20 -> 8926540.1
A27: EBITDA Margin | B27: =IF(B25<>0,B26/B25,0) -> -0.04205253 | C27: =IF(C25<>0,C26/C25,0) -> 0.094027943 | D27: =IF(D25<>0,D26/D25,0) -> 0.14222914 | E27: =IF(E25<>0,E26/E25,0) -> 0.16167429 | F27: =IF(F25<>0,F26/F25,0) -> 0.18492268 | G27: =IF(G25<>0,G26/G25,0) -> 0.20362244 | H27: =IF(H25<>0,H26/H25,0) -> 0.22030405 | I27: =IF(I25<>0,I26/I25,0) -> 0.23829551 | ... K27: =IF(K25<>0,K26/K25,0) -> 0.25418333
A28: Net Profit | B28: ='P&L'!B28 -> -995214.29 | C28: ='P&L'!C28 -> 492531.01 | D28: ='P&L'!D28 -> 1731427 | E28: ='P&L'!E28 -> 2471751.4 | F28: ='P&L'!F28 -> 3415539.6 | G28: ='P&L'!G28 -> 4544097.1 | H28: ='P&L'!H28 -> 5679597.9 | I28: ='P&L'!I28 -> 7074625.4 | ... K28: ='P&L'!K28 -> 8156901.5
A29: EBITDA Health | B29: =IF(B27>0.15,"🟢",IF(B27>0,"🟡","🔴")) -> 🔴 | C29: =IF(C27>0.15,"🟢",IF(C27>0,"🟡","🔴")) -> 🟡 | D29: =IF(D27>0.15,"🟢",IF(D27>0,"🟡","🔴")) -> 🟡 | E29: =IF(E27>0.15,"🟢",IF(E27>0,"🟡","🔴")) -> 🟢 | F29: =IF(F27>0.15,"🟢",IF(F27>0,"🟡","🔴")) -> 🟢 | G29: =IF(G27>0.15,"🟢",IF(G27>0,"🟡","🔴")) -> 🟢 | H29: =IF(H27>0.15,"🟢",IF(H27>0,"🟡","🔴")) -> 🟢 | I29: =IF(I27>0.15,"🟢",IF(I27>0,"🟡","🔴")) -> 🟢 | ... K29: =IF(K27>0.15,"🟢",IF(K27>0,"🟡","🔴")) -> 🟢
A30: Management Mode | B30: =IF(Assumptions!B6=1,"Self-Managed","External (" & TEXT(Assumptions!B123,"0%") & " fee)") -> Self-Managed
A31: Breakeven Utilization | B31: =B50 -> 0.16888908
A32: Y1 Avg Revenue/Patient (AED) | B32: ='Patient Acquisition'!B41 -> 3690.1274 | F32: THRESHOLD ALERTS
F33: KPI | G33: Actual | H33: Threshold | I33: Status
A34: MODEL INTEGRITY CHECKS | F34: Y1 EBITDA Margin | G34: ='P&L'!B21 -> -0.04205253 | H34: -0.8 | I34: =IF(G34>H34,"✓","✗ DEEP LOSS") -> ✓
A35: Check | B35: Delta | C35: Status | D35: Rule | F35: Y3 EBITDA Margin | G35: ='P&L'!D21 -> 0.14222914 | H35: 0.05 | I35: =IF(G35>H35,"✓","✗ NOT PROFITABLE") -> ✓
A36: Revenue ≡ PA × avg price | B36: =Revenue!B13-'Patient Acquisition'!B22*'Patient Acquisition'!B40 -> 0 | C36: =IF(ABS(B36)<1000,"✓ OK","✗ ERROR") -> ✓ OK | D36: Δ < 1,000 | F36: Y5 EBITDA Margin | G36: ='P&L'!F21 -> 0.18492268 | H36: 0.15 | I36: =IF(G36>H36,"✓","⚠ LOW MARGIN") -> ✓
A37: OpEx total ≡ P&L costs | B37: =OpEx!B31-('P&L'!B5+'P&L'!B10+'P&L'!B11+'P&L'!B12+'P&L'!B16+'P&L'!B17+'P&L'!B18+'P&L'!B19) -> 0 | C37: =IF(ABS(B37)<100,"✓ OK","✗ ERROR") -> ✓ OK | D37: Δ < 100 | F37: 10Y IRR | G37: ='Cash Flow & DCF'!C21 -> 0.34484329 | H37: 0.15 | I37: =IF(G37>=H37,"✓","⚠ BELOW 15%") -> ✓
A38: Monthly ≈ Annual Rev | B38: ='Monthly P&L'!N6-'P&L'!B4 -> 29502.631 | C38: =IF(ABS(B38)<1000,"✓ OK","⚠ WARN") -> ⚠ WARN | D38: Δ < 1,000 | F38: LTV:CAC | G38: ='Patient Acquisition'!B47 -> 7.6877655 | H38: 3 | I38: =IF(G38>=H38,"✓","⚠ LOW") -> ✓
A39: PA dept sum = total | B39: ='Patient Acquisition'!B22-'Patient Acquisition'!B85 -> 0 | C39: =IF(ABS(B39)<10,"✓ OK","✗ ERROR") -> ✓ OK | D39: Must match | F39: Y5 Staff Util | G39: =Capacity!F39 -> 0.66711224 | H39: 1 | I39: =IF(G39<=H39,"✓","✗ OVER") -> ✓
A40: Staff util ≤ 100% | B40: =Capacity!B39 -> 0.36571642 | C40: =IF(B40<=1,"✓ OK",IF(B40<=1.2,"⚠ HIGH","✗ OVER")) -> ✓ OK | D40: ≤ 100% | F40: Y5 Room Util | G40: =Capacity!F42 -> 0.611 | H40: 1 | I40: =IF(G40<=H40,"✓","⚠ EXPAND") -> ✓
A41: Room util ≤ 100% | B41: =Capacity!B42 -> 0.229 | C41: =IF(B41<=1,"✓ OK",IF(B41<=1.2,"⚠ HIGH","✗ OVER")) -> ✓ OK | D41: ≤ 100% | F41: ALERT STATUS | I41: =IF(COUNTIF(I34:I40,"✗*")>0,"✗ ALERTS",IF(COUNTIF(I34:I40,"⚠*")>0,"⚠ WARNINGS","✓ ALL CLEAR")) -> ✓ ALL CLEAR
A42: Seasonality avg = 1.0 | B42: =AVERAGE(Assumptions!B235:M235) -> 1.0000833 | C42: =IF(ABS(B42-1)<0.001,"✓ OK","✗ ERROR") -> ✓ OK | D42: Budget-neutral | F42: 1-VAR SENSITIVITY: Revenue Factor | G42: IRR | H42: NPV | I42: Eq.Mult
...

Sheet Assumptions
A1: ARISHA MEDICAL CLINIC — UNIFIED FINANCIAL MODEL
A2: Location: Dubai, Studio City | 10-Year Projection
A4: SCENARIO SELECTOR
A5: Active Scenario | B5: 1 | C5: 1 = 620 sqm (Base) | 2 = 450 sqm (Compact)
A6: Management Mode | B6: 1 | C6: 1 = Self-Managed | 2 = External Management (brand fee)
A7: SCENARIO PARAMETERS
A8: Parameter | B8: 620 sqm | C8: 450 sqm | D8: Active Value | E8: Notes
A9: Clinic Area (sqm) | B9: 620 | C9: 450 | D9: =IF($B$5=1,B9,C9) -> 620
A10: Functional Space (%) | B10: 0.71 | C10: 0.65 | D10: =IF($B$5=1,B10,C10) -> 0.71 | E10: 620: 71% | 450: 65%
A11: Functional Area (sqm) | B11: =B9*B10 -> 440.2 | C11: =C9*C10 -> 292.5 | D11: =IF($B$5=1,B11,C11) -> 440.2
A12: Base Rent Rate (AED/sqm/year) | B12: 1320 | C12: 1320 | D12: =IF($B$5=1,B12,C12) -> 1320 | E12: Studio City market rate
A13: Doctor Days per Week | B13: 5 | C13: 5 | D13: =IF($B$5=1,B13,C13) -> 5 | E13: 40h work week, 5-day rotation
A14: Doctor Hours per Day | B14: 8 | C14: 8 | D14: =IF($B$5=1,B14,C14) -> 8 | E14: Excl. 1h lunch break
A15: Doctor Days per Year | B15: =B13*52 -> 260 | C15: =C13*52 -> 260 | D15: =IF($B$5=1,B15,C15) -> 260 | E15: For staff capacity calc
A16: Clinic Days per Week | B16: 7 | C16: 7 | D16: =IF($B$5=1,B16,C16) -> 7 | E16: Open 7 days, staff rotates
A17: Clinic Days per Year | B17: =B16*52 -> 364 | C17: =C16*52 -> 364 | D17: =IF($B$5=1,B17,C17) -> 364 | E17: For room capacity calc
A18: Clinic Hours per Day | B18: 10 | C18: 10 | D18: =IF($B$5=1,B18,C18) -> 10 | E18: Open hours for room utilization
A19: Max Utilization Rate | B19: 0.87 | C19: 0.87 | D19: =IF($B$5=1,B19,C19) -> 0.87
A20: Weekday Target Utilization | B20: 0.87 | C20: 0.87 | D20: =IF($B$5=1,B20,C20) -> 0.87
A21: Weekend Target Utilization | B21: 0.5 | C21: 0.5 | D21: =IF($B$5=1,B21,C21) -> 0.5
A22: Weekdays per Week | B22: 5 | C22: 5 | D22: =IF($B$5=1,B22,C22) -> 5
A23: Blended Target Utilization (max) | B23: =(B22*B20+(B16-B22)*B21)/B16 -> 0.76428571 | C23: =(C22*C20+(C16-C22)*C21)/C16 -> 0.76428571 | D23: =IF($B$5=1,B23,C23) -> 0.76428571
A24: Rent Deposit (months) | B24: 3 | C24: 3 | D24: =IF($B$5=1,B24,C24) -> 3
A25: Renovation Rate (AED/sqm) | B25: 3800 | C25: 3800 | D25: =IF($B$5=1,B25,C25) -> 3800
A26: Depreciation Period (years) | B26: 7 | C26: 7 | D26: =IF($B$5=1,B26,C26) -> 7 | E26: Equipment & fit-out
A28: STAFF CAPACITY (appointments/year)
A29: Department | B29: Cap 620 | C29: Cap 450 | D29: Active Cap | E29: Notes | F29: FTE 620 | G29: FTE 450 | H29: Rate (p/d)
A30: Ortho/Neuro | B30: =F30*$B$15*H30*$D$19 -> 6786 | C30: =G30*$B$15*H30*$D$19 -> 6786 | D30: =IF($B$5=1,B30,C30) -> 6786 | E30: 45min → 10 p/d (8h÷0.75h) | F30: 3 | G30: 3 | H30: 10
A31: Physio | B31: =F31*$B$15*H31*$D$19 -> 12214.8 | C31: =G31*$B$15*H31*$D$19 -> 10857.6 | D31: =IF($B$5=1,B31,C31) -> 12214.8 | E31: 75min → 6 p/d (8h÷1.25h) | F31: 9 | G31: 8 | H31: 6
A32: Dental | B32: =F32*$B$15*H32*$D$19 -> 2714.4 | C32: =G32*$B$15*H32*$D$19 -> 1809.6 | D32: =IF($B$5=1,B32,C32) -> 2714.4 | E32: 100min → 4 p/d (8h÷1.67h) | F32: 3 | G32: 2 | H32: 4
A33: Cosmetology | B33: =F33*$B$15*H33*$D$19 -> 2714.4 | C33: =G33*$B$15*H33*$D$19 -> 1357.2 | D33: =IF($B$5=1,B33,C33) -> 2714.4 | E33: 75min → 6 p/d (8h÷1.25h) | F33: 2 | G33: 1 | H33: 6
A34: Polyclinic (GP+Gynecologist) | B34: =F34*$B$15*H34*$D$19 -> 4524 | C34: =G34*$B$15*H34*$D$19 -> 4524 | D34: =IF($B$5=1,B34,C34) -> 4524 | E34: 45min → 10 p/d (8h÷0.75h) | F34: 2 | G34: 2 | H34: 10
A35: TOTAL Staff Capacity | B35: =SUM(B30:B34) -> 28953.6 | C35: =SUM(C30:C34) -> 25334.4 | D35: =IF($B$5=1,B35,C35) -> 28953.6 | E35: Cap = FTE × DoctorDays × Rate | F35: =SUM(F30:F34) -> 19 | G35: =SUM(G30:G34) -> 16
A37: ROOM CAPACITY (appointments/year)
A38: Department | B38: Cap 620 | C38: Cap 450 | D38: Active Cap | E38: Notes | F38: Rooms 620 | G38: Rooms 450 | H38: Avg Slot (hrs)
A39: Ortho/Neuro | B39: =F39*(($B$22*52)*FLOOR($B$18/H39,1)*$B$20 + (($B$16-$B$22)*52)*FLOOR($B$18/H39,1)*$B$21) -> 7233.2 | C39: =G39*(($C$22*52)*FLOOR($C$18/H39,1)*$C$20 + (($C$16-$C$22)*52)*FLOOR($C$18/H39,1)*$C$21) -> 3616.6 | D39: =IF($B$5=1,B39,C39) -> 7233.2 | E39: ~45 min consult (2 rooms) | F39: 2 | G39: 1 | H39: 0.75
A40: Physio | B40: =F40*(($B$22*52)*FLOOR($B$18/H40,1)*$B$20 + (($B$16-$B$22)*52)*FLOOR($B$18/H40,1)*$B$21) -> 27820 | C40: =G40*(($C$22*52)*FLOOR($C$18/H40,1)*$C$20 + (($C$16-$C$22)*52)*FLOOR($C$18/H40,1)*$C$21) -> 11128 | D40: =IF($B$5=1,B40,C40) -> 27820 | E40: 2 ind. + hall×5 + hall×3 = 10 | F40: 10 | G40: 4 | H40: 1
A41: Dental | B41: =F41*(($B$22*52)*FLOOR($B$18/H41,1)*$B$20 + (($B$16-$B$22)*52)*FLOOR($B$18/H41,1)*$B$21) -> 5007.6 | C41: =G41*(($C$22*52)*FLOOR($C$18/H41,1)*$C$20 + (($C$16-$C$22)*52)*FLOOR($C$18/H41,1)*$C$21) -> 3338.4 | D41: =IF($B$5=1,B41,C41) -> 5007.6 | E41: 3 chairs × 14 sqm each | F41: 3 | G41: 2 | H41: 1.5
A42: Cosmetology | B42: =F42*(($B$22*52)*FLOOR($B$18/H42,1)*$B$20 + (($B$16-$B$22)*52)*FLOOR($B$18/H42,1)*$B$21) -> 8346 | C42: =G42*(($C$22*52)*FLOOR($C$18/H42,1)*$C$20 + (($C$16-$C$22)*52)*FLOOR($C$18/H42,1)*$C$21) -> 2782 | D42: =IF($B$5=1,B42,C42) -> 8346 | E42: Aesthetic + Vital Signs + Derma | F42: 3 | G42: 1 | H42: 1
A43: Polyclinic (GP+Gynecologist) | B43: =F43*(($B$22*52)*FLOOR($B$18/H43,1)*$B$20 + (($B$16-$B$22)*52)*FLOOR($B$18/H43,1)*$B$21) -> 7233.2 | C43: =G43*(($C$22*52)*FLOOR($C$18/H43,1)*$C$20 + (($C$16-$C$22)*52)*FLOOR($C$18/H43,1)*$C$21) -> 7233.2 | D43: =IF($B$5=1,B43,C43) -> 7233.2 | E43: 1 GP + 1 Gyn, ~45 min each | F43: 2 | G43: 2 | H43: 0.75
...

Sheet Price List
A1: PRICE LIST & SERVICE VOLUMES
A2: Note: Prices increase by inflation rate annually. Volumes scale by scenario.
A4: Hrs/Slot | B4: Service/Product | C4: Base Price | D4: Qty Y1/mo | E4: Qty Y2/mo | F4: Qty Y3/mo | G4: Qty Y4/mo | H4: Qty Y5/mo | I4: Qty Y6/mo | J4: Qty Y7/mo | K4: Qty Y8/mo | L4: Qty Y9/mo | M4: Qty Y10/mo
A5: Physio Clinic
A6: 0.5 | B6: Specialist Consultation | C6: 700 | D6: =ROUND('Patient Acquisition'!B55/12*Assumptions!$B$303,0) -> 93 | E6: =ROUND('Patient Acquisition'!C55/12*Assumptions!$B$303,0) -> 147 | F6: =ROUND('Patient Acquisition'!D55/12*Assumptions!$B$303,0) -> 202 | G6: =ROUND('Patient Acquisition'!E55/12*Assumptions!$B$303,0) -> 225 | H6: =ROUND('Patient Acquisition'!F55/12*Assumptions!$B$303,0) -> 248 | I6: =ROUND('Patient Acquisition'!G55/12*Assumptions!$B$303,0) -> 280 | J6: =ROUND('Patient Acquisition'!H55/12*Assumptions!$B$303,0) -> 310 | K6: =ROUND('Patient Acquisition'!I55/12*Assumptions!$B$303,0) -> 310 | ... M6: =ROUND('Patient Acquisition'!K55/12*Assumptions!$B$303,0) -> 310
A7: 1 | B7: Personal Rehabilitation Session | C7: 600 | D7: =ROUND('Patient Acquisition'!B55/12*Assumptions!$B$304,0) -> 447 | E7: =ROUND('Patient Acquisition'!C55/12*Assumptions!$B$304,0) -> 708 | F7: =ROUND('Patient Acquisition'!D55/12*Assumptions!$B$304,0) -> 969 | G7: =ROUND('Patient Acquisition'!E55/12*Assumptions!$B$304,0) -> 1080 | H7: =ROUND('Patient Acquisition'!F55/12*Assumptions!$B$304,0) -> 1192 | I7: =ROUND('Patient Acquisition'!G55/12*Assumptions!$B$304,0) -> 1342 | J7: =ROUND('Patient Acquisition'!H55/12*Assumptions!$B$304,0) -> 1490 | K7: =ROUND('Patient Acquisition'!I55/12*Assumptions!$B$304,0) -> 1490 | ... M7: =ROUND('Patient Acquisition'!K55/12*Assumptions!$B$304,0) -> 1490
A8: 0.5 | B8: Follow Up Consultation | C8: 350 | D8: =ROUND('Patient Acquisition'!B55/12*Assumptions!$B$305,0) -> 51 | E8: =ROUND('Patient Acquisition'!C55/12*Assumptions!$B$305,0) -> 80 | F8: =ROUND('Patient Acquisition'!D55/12*Assumptions!$B$305,0) -> 110 | G8: =ROUND('Patient Acquisition'!E55/12*Assumptions!$B$305,0) -> 123 | H8: =ROUND('Patient Acquisition'!F55/12*Assumptions!$B$305,0) -> 135 | I8: =ROUND('Patient Acquisition'!G55/12*Assumptions!$B$305,0) -> 152 | J8: =ROUND('Patient Acquisition'!H55/12*Assumptions!$B$305,0) -> 169 | K8: =ROUND('Patient Acquisition'!I55/12*Assumptions!$B$305,0) -> 169 | ... M8: =ROUND('Patient Acquisition'!K55/12*Assumptions!$B$305,0) -> 169
A9: 0.5 | B9: Injections | C9: 700 | D9: =ROUND('Patient Acquisition'!B55/12*Assumptions!$B$306,0) -> 9 | E9: =ROUND('Patient Acquisition'!C55/12*Assumptions!$B$306,0) -> 15 | F9: =ROUND('Patient Acquisition'!D55/12*Assumptions!$B$306,0) -> 20 | G9: =ROUND('Patient Acquisition'!E55/12*Assumptions!$B$306,0) -> 23 | H9: =ROUND('Patient Acquisition'!F55/12*Assumptions!$B$306,0) -> 25 | I9: =ROUND('Patient Acquisition'!G55/12*Assumptions!$B$306,0) -> 28 | J9: =ROUND('Patient Acquisition'!H55/12*Assumptions!$B$306,0) -> 31 | K9: =ROUND('Patient Acquisition'!I55/12*Assumptions!$B$306,0) -> 31 | ... M9: =ROUND('Patient Acquisition'!K55/12*Assumptions!$B$306,0) -> 31
A10: 1 | B10: Orthotics | C10: 1000 | D10: =ROUND('Patient Acquisition'!B55/12*Assumptions!$B$307,0) -> 5 | E10: =ROUND('Patient Acquisition'!C55/12*Assumptions!$B$307,0) -> 7 | F10: =ROUND('Patient Acquisition'!D55/12*Assumptions!$B$307,0) -> 10 | G10: =ROUND('Patient Acquisition'!E55/12*Assumptions!$B$307,0) -> 11 | H10: =ROUND('Patient Acquisition'!F55/12*Assumptions!$B$307,0) -> 12 | I10: =ROUND('Patient Acquisition'!G55/12*Assumptions!$B$307,0) -> 14 | J10: =ROUND('Patient Acquisition'!H55/12*Assumptions!$B$307,0) -> 16 | K10: =ROUND('Patient Acquisition'!I55/12*Assumptions!$B$307,0) -> 16 | ... M10: =ROUND('Patient Acquisition'!K55/12*Assumptions!$B$307,0) -> 16
A11: Dental Clinic
A12: 0.5 | B12: Hygiene | C12: 350 | D12: =ROUND('Patient Acquisition'!B61/12*Assumptions!$B$309,0) -> 39 | E12: =ROUND('Patient Acquisition'!C61/12*Assumptions!$B$309,0) -> 61 | F12: =ROUND('Patient Acquisition'!D61/12*Assumptions!$B$309,0) -> 84 | G12: =ROUND('Patient Acquisition'!E61/12*Assumptions!$B$309,0) -> 94 | H12: =ROUND('Patient Acquisition'!F61/12*Assumptions!$B$309,0) -> 103 | I12: =ROUND('Patient Acquisition'!G61/12*Assumptions!$B$309,0) -> 116 | J12: =ROUND('Patient Acquisition'!H61/12*Assumptions!$B$309,0) -> 125 | K12: =ROUND('Patient Acquisition'!I61/12*Assumptions!$B$309,0) -> 125 | ... M12: =ROUND('Patient Acquisition'!K61/12*Assumptions!$B$309,0) -> 125
A13: 1 | B13: Restorative | C13: 500 | D13: =ROUND('Patient Acquisition'!B61/12*Assumptions!$B$310,0) -> 52 | E13: =ROUND('Patient Acquisition'!C61/12*Assumptions!$B$310,0) -> 82 | F13: =ROUND('Patient Acquisition'!D61/12*Assumptions!$B$310,0) -> 112 | G13: =ROUND('Patient Acquisition'!E61/12*Assumptions!$B$310,0) -> 125 | H13: =ROUND('Patient Acquisition'!F61/12*Assumptions!$B$310,0) -> 138 | I13: =ROUND('Patient Acquisition'!G61/12*Assumptions!$B$310,0) -> 155 | J13: =ROUND('Patient Acquisition'!H61/12*Assumptions!$B$310,0) -> 167 | K13: =ROUND('Patient Acquisition'!I61/12*Assumptions!$B$310,0) -> 167 | ... M13: =ROUND('Patient Acquisition'!K61/12*Assumptions!$B$310,0) -> 167
A14: 2 | B14: Implantology | C14: 3500 | D14: =ROUND('Patient Acquisition'!B61/12*Assumptions!$B$311,0) -> 7 | E14: =ROUND('Patient Acquisition'!C61/12*Assumptions!$B$311,0) -> 10 | F14: =ROUND('Patient Acquisition'!D61/12*Assumptions!$B$311,0) -> 14 | G14: =ROUND('Patient Acquisition'!E61/12*Assumptions!$B$311,0) -> 16 | H14: =ROUND('Patient Acquisition'!F61/12*Assumptions!$B$311,0) -> 17 | I14: =ROUND('Patient Acquisition'!G61/12*Assumptions!$B$311,0) -> 20 | J14: =ROUND('Patient Acquisition'!H61/12*Assumptions!$B$311,0) -> 21 | K14: =ROUND('Patient Acquisition'!I61/12*Assumptions!$B$311,0) -> 21 | ... M14: =ROUND('Patient Acquisition'!K61/12*Assumptions!$B$311,0) -> 21
A15: 1.5 | B15: Aesthetic Dentistry | C15: 2200 | D15: =ROUND('Patient Acquisition'!B61/12*Assumptions!$B$312,0) -> 13 | E15: =ROUND('Patient Acquisition'!C61/12*Assumptions!$B$312,0) -> 21 | F15: =ROUND('Patient Acquisition'!D61/12*Assumptions!$B$312,0) -> 28 | G15: =ROUND('Patient Acquisition'!E61/12*Assumptions!$B$312,0) -> 32 | H15: =ROUND('Patient Acquisition'!F61/12*Assumptions!$B$312,0) -> 35 | I15: =ROUND('Patient Acquisition'!G61/12*Assumptions!$B$312,0) -> 39 | J15: =ROUND('Patient Acquisition'!H61/12*Assumptions!$B$312,0) -> 42 | K15: =ROUND('Patient Acquisition'!I61/12*Assumptions!$B$312,0) -> 42 | ... M15: =ROUND('Patient Acquisition'!K61/12*Assumptions!$B$312,0) -> 42
A16: 0.5 | B16: Follow Up Consultation | C16: 250 | D16: =ROUND('Patient Acquisition'!B61/12*Assumptions!$B$313,0) -> 20 | E16: =ROUND('Patient Acquisition'!C61/12*Assumptions!$B$313,0) -> 31 | F16: =ROUND('Patient Acquisition'!D61/12*Assumptions!$B$313,0) -> 42 | G16: =ROUND('Patient Acquisition'!E61/12*Assumptions!$B$313,0) -> 47 | H16: =ROUND('Patient Acquisition'!F61/12*Assumptions!$B$313,0) -> 52 | I16: =ROUND('Patient Acquisition'!G61/12*Assumptions!$B$313,0) -> 59 | J16: =ROUND('Patient Acquisition'!H61/12*Assumptions!$B$313,0) -> 63 | K16: =ROUND('Patient Acquisition'!I61/12*Assumptions!$B$313,0) -> 63 | ... M16: =ROUND('Patient Acquisition'!K61/12*Assumptions!$B$313,0) -> 63
A17: Polyclinic
A18: 0.5 | B18: GP | C18: 600 | D18: =ROUND('Patient Acquisition'!B67/12,0) -> 43 | E18: =ROUND('Patient Acquisition'!C67/12,0) -> 68 | F18: =ROUND('Patient Acquisition'!D67/12,0) -> 94 | G18: =ROUND('Patient Acquisition'!E67/12,0) -> 104 | H18: =ROUND('Patient Acquisition'!F67/12,0) -> 115 | I18: =ROUND('Patient Acquisition'!G67/12,0) -> 130 | J18: =ROUND('Patient Acquisition'!H67/12,0) -> 144 | K18: =ROUND('Patient Acquisition'!I67/12,0) -> 144 | ... M18: =ROUND('Patient Acquisition'!K67/12,0) -> 144
A19: 0.5 | B19: Gynecology | C19: 600 | D19: =ROUND('Patient Acquisition'!B73/12,0) -> 43 | E19: =ROUND('Patient Acquisition'!C73/12,0) -> 68 | F19: =ROUND('Patient Acquisition'!D73/12,0) -> 94 | G19: =ROUND('Patient Acquisition'!E73/12,0) -> 104 | H19: =ROUND('Patient Acquisition'!F73/12,0) -> 115 | I19: =ROUND('Patient Acquisition'!G73/12,0) -> 130 | J19: =ROUND('Patient Acquisition'!H73/12,0) -> 144 | K19: =ROUND('Patient Acquisition'!I73/12,0) -> 144 | ... M19: =ROUND('Patient Acquisition'!K73/12,0) -> 144
A20: 0.25 | B20: Blood Tests (lab partner) | C20: 300 | D20: =ROUND(('Patient Acquisition'!B67+'Patient Acquisition'!B73)/12*Assumptions!$B$319,0) -> 35 | E20: =ROUND(('Patient Acquisition'!C67+'Patient Acquisition'!C73)/12*Assumptions!$B$319,0) -> 55 | F20: =ROUND(('Patient Acquisition'!D67+'Patient Acquisition'!D73)/12*Assumptions!$B$319,0) -> 75 | G20: =ROUND(('Patient Acquisition'!E67+'Patient Acquisition'!E73)/12*Assumptions!$B$319,0) -> 84 | H20: =ROUND(('Patient Acquisition'!F67+'Patient Acquisition'!F73)/12*Assumptions!$B$319,0) -> 92 | I20: =ROUND(('Patient Acquisition'!G67+'Patient Acquisition'!G73)/12*Assumptions!$B$319,0) -> 104 | J20: =ROUND(('Patient Acquisition'!H67+'Patient Acquisition'!H73)/12*Assumptions!$B$319,0) -> 115 | K20: =ROUND(('Patient Acquisition'!I67+'Patient Acquisition'!I73)/12*Assumptions!$B$319,0) -> 115 | ... M20: =ROUND(('Patient Acquisition'!K67+'Patient Acquisition'!K73)/12*Assumptions!$B$319,0) -> 115
A21: 0.5 | B21: X-Ray | C21: 500 | D21: =ROUND(('Patient Acquisition'!B55/12*Assumptions!$B$303+'Patient Acquisition'!B67/12)*Assumptions!$B$320,0) -> 3 | E21: =ROUND(('Patient Acquisition'!C55/12*Assumptions!$B$303+'Patient Acquisition'!C67/12)*Assumptions!$B$320,0) -> 4 | F21: =ROUND(('Patient Acquisition'!D55/12*Assumptions!$B$303+'Patient Acquisition'!D67/12)*Assumptions!$B$320,0) -> 6 | G21: =ROUND(('Patient Acquisition'!E55/12*Assumptions!$B$303+'Patient Acquisition'!E67/12)*Assumptions!$B$320,0) -> 7 | H21: =ROUND(('Patient Acquisition'!F55/12*Assumptions!$B$303+'Patient Acquisition'!F67/12)*Assumptions!$B$320,0) -> 7 | I21: =ROUND(('Patient Acquisition'!G55/12*Assumptions!$B$303+'Patient Acquisition'!G67/12)*Assumptions!$B$320,0) -> 8 | J21: =ROUND(('Patient Acquisition'!H55/12*Assumptions!$B$303+'Patient Acquisition'!H67/12)*Assumptions!$B$320,0) -> 9 | K21: =ROUND(('Patient Acquisition'!I55/12*Assumptions!$B$303+'Patient Acquisition'!I67/12)*Assumptions!$B$320,0) -> 9 | ... M21: =ROUND(('Patient Acquisition'!K55/12*Assumptions!$B$303+'Patient Acquisition'!K67/12)*Assumptions!$B$320,0) -> 9
A22: 0.5 | B22: Ultrasound | C22: 400 | D22: =ROUND('Patient Acquisition'!B73/12*Assumptions!$B$321,0) -> 11 | E22: =ROUND('Patient Acquisition'!C73/12*Assumptions!$B$321,0) -> 17 | F22: =ROUND('Patient Acquisition'!D73/12*Assumptions!$B$321,0) -> 23 | G22: =ROUND('Patient Acquisition'!E73/12*Assumptions!$B$321,0) -> 26 | H22: =ROUND('Patient Acquisition'!F73/12*Assumptions!$B$321,0) -> 29 | I22: =ROUND('Patient Acquisition'!G73/12*Assumptions!$B$321,0) -> 32 | J22: =ROUND('Patient Acquisition'!H73/12*Assumptions!$B$321,0) -> 36 | K22: =ROUND('Patient Acquisition'!I73/12*Assumptions!$B$321,0) -> 36 | ... M22: =ROUND('Patient Acquisition'!K73/12*Assumptions!$B$321,0) -> 36
A23: Cosmetology
A24: 1 | B24: Session | C24: 450 | D24: =ROUND('Patient Acquisition'!B79/12*Assumptions!$B$323,0) -> 242 | E24: =ROUND('Patient Acquisition'!C79/12*Assumptions!$B$323,0) -> 383 | F24: =ROUND('Patient Acquisition'!D79/12*Assumptions!$B$323,0) -> 525 | G24: =ROUND('Patient Acquisition'!E79/12*Assumptions!$B$323,0) -> 585 | H24: =ROUND('Patient Acquisition'!F79/12*Assumptions!$B$323,0) -> 645 | I24: =ROUND('Patient Acquisition'!G79/12*Assumptions!$B$323,0) -> 696 | J24: =ROUND('Patient Acquisition'!H79/12*Assumptions!$B$323,0) -> 696 | K24: =ROUND('Patient Acquisition'!I79/12*Assumptions!$B$323,0) -> 696 | ... M24: =ROUND('Patient Acquisition'!K79/12*Assumptions!$B$323,0) -> 696
A25: Wellness Packages
B26: Essential Package | C26: 1200
B27: Premium Package | C27: 2200
B28: Elite Package | C28: 3800

Sheet Revenue
A1: REVENUE PROJECTION (10 YEARS)
A2: Prices adjusted annually by inflation rate
A4: Category | B4: Year 1 | C4: Year 2 | D4: Year 3 | E4: Year 4 | F4: Year 5 | G4: Year 6 | H4: Year 7 | I4: Year 8 | J4: Year 9 | K4: Year 10
A5: Inflation Factor | B5: =1 -> 1 | C5: =B5*(1+Assumptions!$B$47) -> 1.04 | D5: =C5*(1+Assumptions!$B$47) -> 1.0816 | E5: =D5*(1+Assumptions!$B$47) -> 1.124864 | F5: =E5*(1+Assumptions!$B$47) -> 1.1698586 | G5: =F5*(1+Assumptions!$B$47) -> 1.2166529 | H5: =G5*(1+Assumptions!$B$47) -> 1.265319 | I5: =H5*(1+Assumptions!$B$47) -> 1.3159318 | J5: =I5*(1+Assumptions!$B$47) -> 1.3685691 | K5: =J5*(1+Assumptions!$B$47) -> 1.4233118
A6: Utilization Factor (Organic + Marketing) | B6: 1 | C6: 1 | D6: 1 | E6: 1 | F6: 1 | G6: 1 | H6: 1 | I6: 1 | J6: 1 | K6: 1
A8: Physio Clinic | B8: ='Price List'!D6*12*'Price List'!C6*B5*B6+'Price List'!D7*12*'Price List'!C7*B5*B6+'Price List'!D8*12*'Price List'!C8*B5*B6+'Price List'!D9*12*'Price List'!C9*B5*B6+'Price List'!D10*12*'Price List'!C10*B5*B6 -> 4349400 | C8: ='Price List'!E6*12*'Price List'!C6*C5*C6+'Price List'!E7*12*'Price List'!C7*C5*C6+'Price List'!E8*12*'Price List'!C8*C5*C6+'Price List'!E9*12*'Price List'!C9*C5*C6+'Price List'!E10*12*'Price List'!C10*C5*C6 -> 7153536 | D8: ='Price List'!F6*12*'Price List'!C6*D5*D6+'Price List'!F7*12*'Price List'!C7*D5*D6+'Price List'!F8*12*'Price List'!C8*D5*D6+'Price List'!F9*12*'Price List'!C9*D5*D6+'Price List'!F10*12*'Price List'!C10*D5*D6 -> 10192566 | E8: ='Price List'!G6*12*'Price List'!C6*E5*E6+'Price List'!G7*12*'Price List'!C7*E5*E6+'Price List'!G8*12*'Price List'!C8*E5*E6+'Price List'!G9*12*'Price List'!C9*E5*E6+'Price List'!G10*12*'Price List'!C10*E5*E6 -> 11819846 | F8: ='Price List'!H6*12*'Price List'!C6*F5*F6+'Price List'!H7*12*'Price List'!C7*F5*F6+'Price List'!H8*12*'Price List'!C8*F5*F6+'Price List'!H9*12*'Price List'!C9*F5*F6+'Price List'!H10*12*'Price List'!C10*F5*F6 -> 13554683 | G8: ='Price List'!I6*12*'Price List'!C6*G5*G6+'Price List'!I7*12*'Price List'!C7*G5*G6+'Price List'!I8*12*'Price List'!C8*G5*G6+'Price List'!I9*12*'Price List'!C9*G5*G6+'Price List'!I10*12*'Price List'!C10*G5*G6 -> 15884620 | H8: ='Price List'!J6*12*'Price List'!C6*H5*H6+'Price List'!J7*12*'Price List'!C7*H5*H6+'Price List'!J8*12*'Price List'!C8*H5*H6+'Price List'!J9*12*'Price List'!C9*H5*H6+'Price List'!J10*12*'Price List'!C10*H5*H6 -> 18339787 | I8: ='Price List'!K6*12*'Price List'!C6*I5*I6+'Price List'!K7*12*'Price List'!C7*I5*I6+'Price List'!K8*12*'Price List'!C8*I5*I6+'Price List'!K9*12*'Price List'!C9*I5*I6+'Price List'!K10*12*'Price List'!C10*I5*I6 -> 19073378 | J8: ='Price List'!L6*12*'Price List'!C6*J5*J6+'Price List'!L7*12*'Price List'!C7*J5*J6+'Price List'!L8*12*'Price List'!C8*J5*J6+'Price List'!L9*12*'Price List'!C9*J5*J6+'Price List'!L10*12*'Price List'!C10*J5*J6 -> 19836314 | K8: ='Price List'!M6*12*'Price List'!C6*K5*K6+'Price List'!M7*12*'Price List'!C7*K5*K6+'Price List'!M8*12*'Price List'!C8*K5*K6+'Price List'!M9*12*'Price List'!C9*K5*K6+'Price List'!M10*12*'Price List'!C10*K5*K6 -> 20629766
A9: Dental Clinic | B9: ='Price List'!D12*12*'Price List'!C12*B5*B6+'Price List'!D13*12*'Price List'!C13*B5*B6+'Price List'!D14*12*'Price List'!C14*B5*B6+'Price List'!D15*12*'Price List'!C15*B5*B6+'Price List'!D16*12*'Price List'!C16*B5*B6 -> 1173000 | C9: ='Price List'!E12*12*'Price List'!C12*C5*C6+'Price List'!E13*12*'Price List'!C13*C5*C6+'Price List'!E14*12*'Price List'!C14*C5*C6+'Price List'!E15*12*'Price List'!C15*C5*C6+'Price List'!E16*12*'Price List'!C16*C5*C6 -> 1888224 | D9: ='Price List'!F12*12*'Price List'!C12*D5*D6+'Price List'!F13*12*'Price List'!C13*D5*D6+'Price List'!F14*12*'Price List'!C14*D5*D6+'Price List'!F15*12*'Price List'!C15*D5*D6+'Price List'!F16*12*'Price List'!C16*D5*D6 -> 2680204.8 | E9: ='Price List'!G12*12*'Price List'!C12*E5*E6+'Price List'!G13*12*'Price List'!C13*E5*E6+'Price List'!G14*12*'Price List'!C14*E5*E6+'Price List'!G15*12*'Price List'!C15*E5*E6+'Price List'!G16*12*'Price List'!C16*E5*E6 -> 3152543.8 | F9: ='Price List'!H12*12*'Price List'!C12*F5*F6+'Price List'!H13*12*'Price List'!C13*F5*F6+'Price List'!H14*12*'Price List'!C14*F5*F6+'Price List'!H15*12*'Price List'!C15*F5*F6+'Price List'!H16*12*'Price List'!C16*F5*F6 -> 3573450 | G9: ='Price List'!I12*12*'Price List'!C12*G5*G6+'Price List'!I13*12*'Price List'!C13*G5*G6+'Price List'!I14*12*'Price List'!C14*G5*G6+'Price List'!I15*12*'Price List'!C15*G5*G6+'Price List'!I16*12*'Price List'!C16*G5*G6 -> 4214242.3 | H9: ='Price List'!J12*12*'Price List'!C12*H5*H6+'Price List'!J13*12*'Price List'!C13*H5*H6+'Price List'!J14*12*'Price List'!C14*H5*H6+'Price List'!J15*12*'Price List'!C15*H5*H6+'Price List'!J16*12*'Price List'!C16*H5*H6 -> 4690284.5 | I9: ='Price List'!K12*12*'Price List'!C12*I5*I6+'Price List'!K13*12*'Price List'!C13*I5*I6+'Price List'!K14*12*'Price List'!C14*I5*I6+'Price List'!K15*12*'Price List'!C15*I5*I6+'Price List'!K16*12*'Price List'!C16*I5*I6 -> 4877895.9 | J9: ='Price List'!L12*12*'Price List'!C12*J5*J6+'Price List'!L13*12*'Price List'!C13*J5*J6+'Price List'!L14*12*'Price List'!C14*J5*J6+'Price List'!L15*12*'Price List'!C15*J5*J6+'Price List'!L16*12*'Price List'!C16*J5*J6 -> 5073011.8 | K9: ='Price List'!M12*12*'Price List'!C12*K5*K6+'Price List'!M13*12*'Price List'!C13*K5*K6+'Price List'!M14*12*'Price List'!C14*K5*K6+'Price List'!M15*12*'Price List'!C15*K5*K6+'Price List'!M16*12*'Price List'!C16*K5*K6 -> 5275932.2
A10: Polyclinic | B10: ='Price List'!D18*12*'Price List'!C18*B5*B6+'Price List'!D19*12*'Price List'!C19*B5*B6+'Price List'!D20*12*'Price List'!C20*B5*B6+'Price List'!D21*12*'Price List'!C21*B5*B6+'Price List'!D22*12*'Price List'!C22*B5*B6 -> 816000 | C10: ='Price List'!E18*12*'Price List'!C18*C5*C6+'Price List'!E19*12*'Price List'!C19*C5*C6+'Price List'!E20*12*'Price List'!C20*C5*C6+'Price List'!E21*12*'Price List'!C21*C5*C6+'Price List'!E22*12*'Price List'!C22*C5*C6 -> 1334112 | D10: ='Price List'!F18*12*'Price List'!C18*D5*D6+'Price List'!F19*12*'Price List'!C19*D5*D6+'Price List'!F20*12*'Price List'!C20*D5*D6+'Price List'!F21*12*'Price List'!C21*D5*D6+'Price List'!F22*12*'Price List'!C22*D5*D6 -> 1914432 | E10: ='Price List'!G18*12*'Price List'!C18*E5*E6+'Price List'!G19*12*'Price List'!C19*E5*E6+'Price List'!G20*12*'Price List'!C20*E5*E6+'Price List'!G21*12*'Price List'!C21*E5*E6+'Price List'!G22*12*'Price List'!C22*E5*E6 -> 2212382.5 | F10: ='Price List'!H18*12*'Price List'!C18*F5*F6+'Price List'!H19*12*'Price List'!C19*F5*F6+'Price List'!H20*12*'Price List'!C20*F5*F6+'Price List'!H21*12*'Price List'!C21*F5*F6+'Price List'!H22*12*'Price List'!C22*F5*F6 -> 2536721.3 | G10: ='Price List'!I18*12*'Price List'!C18*G5*G6+'Price List'!I19*12*'Price List'!C19*G5*G6+'Price List'!I20*12*'Price List'!C20*G5*G6+'Price List'!I21*12*'Price List'!C21*G5*G6+'Price List'!I22*12*'Price List'!C22*G5*G6 -> 2978366.3 | H10: ='Price List'!J18*12*'Price List'!C18*H5*H6+'Price List'!J19*12*'Price List'!C19*H5*H6+'Price List'!J20*12*'Price List'!C20*H5*H6+'Price List'!J21*12*'Price List'!C21*H5*H6+'Price List'!J22*12*'Price List'!C22*H5*H6 -> 3434581.9 | I10: ='Price List'!K18*12*'Price List'!C18*I5*I6+'Price List'!K19*12*'Price List'!C19*I5*I6+'Price List'!K20*12*'Price List'!C20*I5*I6+'Price List'!K21*12*'Price List'!C21*I5*I6+'Price List'!K22*12*'Price List'!C22*I5*I6 -> 3571965.2 | J10: ='Price List'!L18*12*'Price List'!C18*J5*J6+'Price List'!L19*12*'Price List'!C19*J5*J6+'Price List'!L20*12*'Price List'!C20*J5*J6+'Price List'!L21*12*'Price List'!C21*J5*J6+'Price List'!L22*12*'Price List'!C22*J5*J6 -> 3714843.8 | K10: ='Price List'!M18*12*'Price List'!C18*K5*K6+'Price List'!M19*12*'Price List'!C19*K5*K6+'Price List'!M20*12*'Price List'!C20*K5*K6+'Price List'!M21*12*'Price List'!C21*K5*K6+'Price List'!M22*12*'Price List'!C22*K5*K6 -> 3863437.6
A11: Cosmetology | B11: ='Price List'!D24*12*'Price List'!C24*B5*B6 -> 1306800 | C11: ='Price List'!E24*12*'Price List'!C24*C5*C6 -> 2150928 | D11: ='Price List'!F24*12*'Price List'!C24*D5*D6 -> 3066336 | E11: ='Price List'!G24*12*'Price List'!C24*E5*E6 -> 3553445.4 | F11: ='Price List'!H24*12*'Price List'!C24*F5*F6 -> 4074617.4 | G11: ='Price List'!I24*12*'Price List'!C24*G5*G6 -> 4572668.3 | H11: ='Price List'!J24*12*'Price List'!C24*H5*H6 -> 4755575 | I11: ='Price List'!K24*12*'Price List'!C24*I5*I6 -> 4945798 | J11: ='Price List'!L24*12*'Price List'!C24*J5*J6 -> 5143629.9 | K11: ='Price List'!M24*12*'Price List'!C24*K5*K6 -> 5349375.1
A12: Wellness Packages | B12: 0 | C12: 0 | D12: 0 | E12: 0 | F12: 0 | G12: 0 | H12: 0 | I12: 0 | J12: 0 | K12: 0
A13: TOTAL REVENUE | B13: =SUM(B8:B12) -> 7645200 | C13: =SUM(C8:C12) -> 12526800 | D13: =SUM(D8:D12) -> 17853539 | E13: =SUM(E8:E12) -> 20738218 | F13: =SUM(F8:F12) -> 23739472 | G13: =SUM(G8:G12) -> 27649897 | H13: =SUM(H8:H12) -> 31220228 | I13: =SUM(I8:I12) -> 32469038 | ... K13: =SUM(K8:K12) -> 35118511
A14: YoY Growth | B14: - | C14: =C13/B13-1 -> 0.63851829 | D14: =D13/C13-1 -> 0.4252274 | E14: =E13/D13-1 -> 0.16157464 | F14: =F13/E13-1 -> 0.14472093 | G14: =G13/F13-1 -> 0.16472251 | H14: =H13/G13-1 -> 0.12912638 | I14: =I13/H13-1 -> 0.04 | J14: =J13/I13-1 -> 0.04 | K14: =K13/J13-1 -> 0.04
A15: AVG Monthly Revenue | B15: =B13/12 -> 637100 | C15: =C13/12 -> 1043900 | D15: =D13/12 -> 1487794.9 | E15: =E13/12 -> 1728184.8 | F15: =F13/12 -> 1978289.3 | G15: =G13/12 -> 2304158.1 | H15: =H13/12 -> 2601685.7 | I15: =I13/12 -> 2705753.1 | ... K15: =K13/12 -> 2926542.6
A17: (Channel efficiency metrics → see Patient Acquisition sheet, rows 38-50)

Sheet Capacity
A1: CAPACITY ANALYSIS
A3: Metric | B3: Year 1 | C3: Year 2 | D3: Year 3 | E3: Year 4 | F3: Year 5 | G3: Year 6 | H3: Year 7 | I3: Year 8 | J3: Year 9 | K3: Year 10
A4: Volume Factor | B4: =Revenue!B6 -> 1 | C4: =Revenue!C6 -> 1 | D4: =Revenue!D6 -> 1 | E4: =Revenue!E6 -> 1 | F4: =Revenue!F6 -> 1 | G4: =Revenue!G6 -> 1 | H4: =Revenue!H6 -> 1 | I4: =Revenue!I6 -> 1 | ... K4: =Revenue!K6 -> 1
A6: Physio Clinic
A7: Annual Visits | B7: ='Patient Acquisition'!B55 -> 7251.2943 | C7: ='Patient Acquisition'!C55 -> 11494.41 | D7: ='Patient Acquisition'!D55 -> 15737.525 | E7: ='Patient Acquisition'!E55 -> 17542.433 | F7: ='Patient Acquisition'!F55 -> 19347.34 | G7: ='Patient Acquisition'!G55 -> 21785.548 | H7: ='Patient Acquisition'!H55 -> 24192.091 | I7: ='Patient Acquisition'!I55 -> 24192.091 | ... K7: ='Patient Acquisition'!K55 -> 24192.091
A8: Staff Utilization | B8: =IF(Assumptions!C186>0,B7/(Assumptions!C186/Assumptions!$D$19),0) -> 0.51647395 | C8: =IF(Assumptions!D186>0,C7/(Assumptions!D186/Assumptions!$D$19),0) -> 0.81869015 | D8: =IF(Assumptions!E186>0,D7/(Assumptions!E186/Assumptions!$D$19),0) -> 0.84067977 | E8: =IF(Assumptions!F186>0,E7/(Assumptions!F186/Assumptions!$D$19),0) -> 0.86501147 | F8: =IF(Assumptions!G186>0,F7/(Assumptions!G186/Assumptions!$D$19),0) -> 0.82680939 | G8: =IF(Assumptions!H186>0,G7/(Assumptions!H186/Assumptions!$D$19),0) -> 0.82147617 | H8: =IF(Assumptions!I186>0,H7/(Assumptions!I186/Assumptions!$D$19),0) -> 0.8615417 | I8: =IF(Assumptions!J186>0,I7/(Assumptions!J186/Assumptions!$D$19),0) -> 0.8615417 | ... K8: =IF(Assumptions!L186>0,K7/(Assumptions!L186/Assumptions!$D$19),0) -> 0.8161974
A9: Room Utilization | B9: =IF(Assumptions!$D$40>0,B7/Assumptions!$D$40,0) -> 0.26065041 | C9: =IF(Assumptions!$D$40>0,C7/Assumptions!$D$40,0) -> 0.41317073 | D9: =IF(Assumptions!$D$40>0,D7/Assumptions!$D$40,0) -> 0.56569106 | E9: =IF(Assumptions!$D$40>0,E7/Assumptions!$D$40,0) -> 0.63056911 | F9: =IF(Assumptions!$D$40>0,F7/Assumptions!$D$40,0) -> 0.69544715 | G9: =IF(Assumptions!$D$40>0,G7/Assumptions!$D$40,0) -> 0.78308943 | H9: =IF(Assumptions!$D$40>0,H7/Assumptions!$D$40,0) -> 0.8695935 | I9: =IF(Assumptions!$D$40>0,I7/Assumptions!$D$40,0) -> 0.8695935 | ... K9: =IF(Assumptions!$D$40>0,K7/Assumptions!$D$40,0) -> 0.8695935
A11: Dental Clinic
A12: Annual Visits | B12: ='Patient Acquisition'!B61 -> 1553.8488 | C12: ='Patient Acquisition'!C61 -> 2463.0878 | D12: ='Patient Acquisition'!D61 -> 3372.3268 | E12: ='Patient Acquisition'!E61 -> 3759.0927 | F12: ='Patient Acquisition'!F61 -> 4145.8585 | G12: ='Patient Acquisition'!G61 -> 4668.3317 | H12: ='Patient Acquisition'!H61 -> 5007.6 | I12: ='Patient Acquisition'!I61 -> 5007.6 | ... K12: ='Patient Acquisition'!K61 -> 5007.6
A13: Staff Utilization | B13: =IF(Assumptions!C187>0,B12/(Assumptions!C187/Assumptions!$D$19),0) -> 0.49802846 | C13: =IF(Assumptions!D187>0,C12/(Assumptions!D187/Assumptions!$D$19),0) -> 0.78945122 | D13: =IF(Assumptions!E187>0,D12/(Assumptions!E187/Assumptions!$D$19),0) -> 0.81065549 | E13: =IF(Assumptions!F187>0,E12/(Assumptions!F187/Assumptions!$D$19),0) -> 0.72290244 | F13: =IF(Assumptions!G187>0,F12/(Assumptions!G187/Assumptions!$D$19),0) -> 0.79728049 | G13: =IF(Assumptions!H187>0,G12/(Assumptions!H187/Assumptions!$D$19),0) -> 0.74813008 | H13: =IF(Assumptions!I187>0,H12/(Assumptions!I187/Assumptions!$D$19),0) -> 0.8025 | I13: =IF(Assumptions!J187>0,I12/(Assumptions!J187/Assumptions!$D$19),0) -> 0.8025 | ... K13: =IF(Assumptions!L187>0,K12/(Assumptions!L187/Assumptions!$D$19),0) -> 0.8025
A14: Room Utilization | B14: =IF(Assumptions!$D$41>0,B12/Assumptions!$D$41,0) -> 0.3102981 | C14: =IF(Assumptions!$D$41>0,C12/Assumptions!$D$41,0) -> 0.49186992 | D14: =IF(Assumptions!$D$41>0,D12/Assumptions!$D$41,0) -> 0.67344173 | E14: =IF(Assumptions!$D$41>0,E12/Assumptions!$D$41,0) -> 0.75067751 | F14: =IF(Assumptions!$D$41>0,F12/Assumptions!$D$41,0) -> 0.82791328 | G14: =IF(Assumptions!$D$41>0,G12/Assumptions!$D$41,0) -> 0.93224932 | H14: =IF(Assumptions!$D$41>0,H12/Assumptions!$D$41,0) -> 1 | I14: =IF(Assumptions!$D$41>0,I12/Assumptions!$D$41,0) -> 1 | ... K14: =IF(Assumptions!$D$41>0,K12/Assumptions!$D$41,0) -> 1
A16: GP
A17: Annual Visits | B17: ='Patient Acquisition'!B67 -> 517.94959 | C17: ='Patient Acquisition'!C67 -> 821.02927 | D17: ='Patient Acquisition'!D67 -> 1124.1089 | E17: ='Patient Acquisition'!E67 -> 1253.0309 | F17: ='Patient Acquisition'!F67 -> 1381.9528 | G17: ='Patient Acquisition'!G67 -> 1556.1106 | H17: ='Patient Acquisition'!H67 -> 1728.0065 | I17: ='Patient Acquisition'!I67 -> 1728.0065 | ... K17: ='Patient Acquisition'!K67 -> 1728.0065
A18: Staff Utilization | B18: =IF(Assumptions!C189*Assumptions!$B$315>0,B17/(Assumptions!C189*Assumptions!$B$315/Assumptions!$D$19),0) -> 0.19921138 | C18: =IF(Assumptions!D189*Assumptions!$B$315>0,C17/(Assumptions!D189*Assumptions!$B$315/Assumptions!$D$19),0) -> 0.31578049 | D18: =IF(Assumptions!E189*Assumptions!$B$315>0,D17/(Assumptions!E189*Assumptions!$B$315/Assumptions!$D$19),0) -> 0.43234959 | E18: =IF(Assumptions!F189*Assumptions!$B$315>0,E17/(Assumptions!F189*Assumptions!$B$315/Assumptions!$D$19),0) -> 0.48193496 | F18: =IF(Assumptions!G189*Assumptions!$B$315>0,F17/(Assumptions!G189*Assumptions!$B$315/Assumptions!$D$19),0) -> 0.53152033 | G18: =IF(Assumptions!H189*Assumptions!$B$315>0,G17/(Assumptions!H189*Assumptions!$B$315/Assumptions!$D$19),0) -> 0.59850407 | H18: =IF(Assumptions!I189*Assumptions!$B$315>0,H17/(Assumptions!I189*Assumptions!$B$315/Assumptions!$D$19),0) -> 0.66461789 | I18: =IF(Assumptions!J189*Assumptions!$B$315>0,I17/(Assumptions!J189*Assumptions!$B$315/Assumptions!$D$19),0) -> 0.66461789 | ... K18: =IF(Assumptions!L189*Assumptions!$B$315>0,K17/(Assumptions!L189*Assumptions!$B$315/Assumptions!$D$19),0) -> 0.66461789
A19: Room Utilization | B19: =IF(Assumptions!$D$43*Assumptions!$B$315>0,B17/(Assumptions!$D$43*Assumptions!$B$315),0) -> 0.14321451 | C19: =IF(Assumptions!$D$43*Assumptions!$B$315>0,C17/(Assumptions!$D$43*Assumptions!$B$315),0) -> 0.22701689 | D19: =IF(Assumptions!$D$43*Assumptions!$B$315>0,D17/(Assumptions!$D$43*Assumptions!$B$315),0) -> 0.31081926 | E19: =IF(Assumptions!$D$43*Assumptions!$B$315>0,E17/(Assumptions!$D$43*Assumptions!$B$315),0) -> 0.34646654 | F19: =IF(Assumptions!$D$43*Assumptions!$B$315>0,F17/(Assumptions!$D$43*Assumptions!$B$315),0) -> 0.38211382 | G19: =IF(Assumptions!$D$43*Assumptions!$B$315>0,G17/(Assumptions!$D$43*Assumptions!$B$315),0) -> 0.43026892 | H19: =IF(Assumptions!$D$43*Assumptions!$B$315>0,H17/(Assumptions!$D$43*Assumptions!$B$315),0) -> 0.47779862 | I19: =IF(Assumptions!$D$43*Assumptions!$B$315>0,I17/(Assumptions!$D$43*Assumptions!$B$315),0) -> 0.47779862 | ... K19: =IF(Assumptions!$D$43*Assumptions!$B$315>0,K17/(Assumptions!$D$43*Assumptions!$B$315),0) -> 0.47779862
A21: Gynecology
A22: Annual Visits | B22: ='Patient Acquisition'!B73 -> 517.94959 | C22: ='Patient Acquisition'!C73 -> 821.02927 | D22: ='Patient Acquisition'!D73 -> 1124.1089 | E22: ='Patient Acquisition'!E73 -> 1253.0309 | F22: ='Patient Acquisition'!F73 -> 1381.9528 | G22: ='Patient Acquisition'!G73 -> 1556.1106 | H22: ='Patient Acquisition'!H73 -> 1728.0065 | I22: ='Patient Acquisition'!I73 -> 1728.0065 | ... K22: ='Patient Acquisition'!K73 -> 1728.0065
A23: Staff Utilization | B23: =IF(Assumptions!C189*Assumptions!$B$316>0,B22/(Assumptions!C189*Assumptions!$B$316/Assumptions!$D$19),0) -> 0.19921138 | C23: =IF(Assumptions!D189*Assumptions!$B$316>0,C22/(Assumptions!D189*Assumptions!$B$316/Assumptions!$D$19),0) -> 0.31578049 | D23: =IF(Assumptions!E189*Assumptions!$B$316>0,D22/(Assumptions!E189*Assumptions!$B$316/Assumptions!$D$19),0) -> 0.43234959 | E23: =IF(Assumptions!F189*Assumptions!$B$316>0,E22/(Assumptions!F189*Assumptions!$B$316/Assumptions!$D$19),0) -> 0.48193496 | F23: =IF(Assumptions!G189*Assumptions!$B$316>0,F22/(Assumptions!G189*Assumptions!$B$316/Assumptions!$D$19),0) -> 0.53152033 | G23: =IF(Assumptions!H189*Assumptions!$B$316>0,G22/(Assumptions!H189*Assumptions!$B$316/Assumptions!$D$19),0) -> 0.59850407 | H23: =IF(Assumptions!I189*Assumptions!$B$316>0,H22/(Assumptions!I189*Assumptions!$B$316/Assumptions!$D$19),0) -> 0.66461789 | I23: =IF(Assumptions!J189*Assumptions!$B$316>0,I22/(Assumptions!J189*Assumptions!$B$316/Assumptions!$D$19),0) -> 0.66461789 | ... K23: =IF(Assumptions!L189*Assumptions!$B$316>0,K22/(Assumptions!L189*Assumptions!$B$316/Assumptions!$D$19),0) -> 0.66461789
A24: Room Utilization | B24: =IF(Assumptions!$D$43*Assumptions!$B$316>0,B22/(Assumptions!$D$43*Assumptions!$B$316),0) -> 0.14321451 | C24: =IF(Assumptions!$D$43*Assumptions!$B$316>0,C22/(Assumptions!$D$43*Assumptions!$B$316),0) -> 0.22701689 | D24: =IF(Assumptions!$D$43*Assumptions!$B$316>0,D22/(Assumptions!$D$43*Assumptions!$B$316),0) -> 0.31081926 | E24: =IF(Assumptions!$D$43*Assumptions!$B$316>0,E22/(Assumptions!$D$43*Assumptions!$B$316),0) -> 0.34646654 | F24: =IF(Assumptions!$D$43*Assumptions!$B$316>0,F22/(Assumptions!$D$43*Assumptions!$B$316),0) -> 0.38211382 | G24: =IF(Assumptions!$D$43*Assumptions!$B$316>0,G22/(Assumptions!$D$43*Assumptions!$B$316),0) -> 0.43026892 | H24: =IF(Assumptions!$D$43*Assumptions!$B$316>0,H22/(Assumptions!$D$43*Assumptions!$B$316),0) -> 0.47779862 | I24: =IF(Assumptions!$D$43*Assumptions!$B$316>0,I22/(Assumptions!$D$43*Assumptions!$B$316),0) -> 0.47779862 | ... K24: =IF(Assumptions!$D$43*Assumptions!$B$316>0,K22/(Assumptions!$D$43*Assumptions!$B$316),0) -> 0.47779862
A25: Cosmetology
A26: Annual Visits | B26: ='Patient Acquisition'!B79 -> 2900.5177 | C26: ='Patient Acquisition'!C79 -> 4597.7639 | D26: ='Patient Acquisition'!D79 -> 6295.0101 | E26: ='Patient Acquisition'!E79 -> 7016.973 | F26: ='Patient Acquisition'!F79 -> 7738.9359 | G26: ='Patient Acquisition'!G79 -> 8346 | H26: ='Patient Acquisition'!H79 -> 8346 | I26: ='Patient Acquisition'!I79 -> 8346 | ... K26: ='Patient Acquisition'!K79 -> 8346
A27: Staff Utilization | B27: =IF(Assumptions!C188>0,B26/(Assumptions!C188/Assumptions!$D$19),0) -> 0.61976874 | C27: =IF(Assumptions!D188>0,C26/(Assumptions!D188/Assumptions!$D$19),0) -> 0.73682114 | D27: =IF(Assumptions!E188>0,D26/(Assumptions!E188/Assumptions!$D$19),0) -> 0.80705257 | E27: =IF(Assumptions!F188>0,E26/(Assumptions!F188/Assumptions!$D$19),0) -> 0.7496766 | F27: =IF(Assumptions!G188>0,F26/(Assumptions!G188/Assumptions!$D$19),0) -> 0.82680939 | G27: =IF(Assumptions!H188>0,G26/(Assumptions!H188/Assumptions!$D$19),0) -> 0.76428571 | H27: =IF(Assumptions!I188>0,H26/(Assumptions!I188/Assumptions!$D$19),0) -> 0.76428571 | I27: =IF(Assumptions!J188>0,I26/(Assumptions!J188/Assumptions!$D$19),0) -> 0.76428571 | ... K27: =IF(Assumptions!L188>0,K26/(Assumptions!L188/Assumptions!$D$19),0) -> 0.76428571
A28: Room Utilization | B28: =IF(Assumptions!$D$42>0,B26/Assumptions!$D$42,0) -> 0.34753388 | C28: =IF(Assumptions!$D$42>0,C26/Assumptions!$D$42,0) -> 0.55089431 | D28: =IF(Assumptions!$D$42>0,D26/Assumptions!$D$42,0) -> 0.75425474 | E28: =IF(Assumptions!$D$42>0,E26/Assumptions!$D$42,0) -> 0.84075881 | F28: =IF(Assumptions!$D$42>0,F26/Assumptions!$D$42,0) -> 0.92726287 | G28: =IF(Assumptions!$D$42>0,G26/Assumptions!$D$42,0) -> 1 | H28: =IF(Assumptions!$D$42>0,H26/Assumptions!$D$42,0) -> 1 | I28: =IF(Assumptions!$D$42>0,I26/Assumptions!$D$42,0) -> 1 | ... K28: =IF(Assumptions!$D$42>0,K26/Assumptions!$D$42,0) -> 1
A30: Ortho/Neuro (within Physio dept)
A31: Staff Capacity (annual) | B31: =Assumptions!$D$30 -> 6786 | C31: =Assumptions!$D$30 -> 6786 | D31: =Assumptions!$D$30 -> 6786 | E31: =Assumptions!$D$30 -> 6786 | F31: =Assumptions!$D$30 -> 6786 | G31: =Assumptions!$D$30 -> 6786 | H31: =Assumptions!$D$30 -> 6786 | I31: =Assumptions!$D$30 -> 6786 | ... K31: =Assumptions!$D$30 -> 6786
A32: Room Capacity (annual) | B32: =Assumptions!$D$39 -> 7233.2 | C32: =Assumptions!$D$39 -> 7233.2 | D32: =Assumptions!$D$39 -> 7233.2 | E32: =Assumptions!$D$39 -> 7233.2 | F32: =Assumptions!$D$39 -> 7233.2 | G32: =Assumptions!$D$39 -> 7233.2 | H32: =Assumptions!$D$39 -> 7233.2 | I32: =Assumptions!$D$39 -> 7233.2 | ... K32: =Assumptions!$D$39 -> 7233.2
A34: OVERALL CLINIC UTILIZATION
A35: Metric | B35: Year 1 | C35: Year 2 | D35: Year 3 | E35: Year 4 | F35: Year 5 | G35: Year 6 | H35: Year 7 | I35: Year 8 | J35: Year 9 | K35: Year 10
A36: Total Visits (from PA) | B36: ='Patient Acquisition'!B85 -> 12741.56 | C36: ='Patient Acquisition'!C85 -> 20197.32 | D36: ='Patient Acquisition'!D85 -> 27653.08 | E36: ='Patient Acquisition'!E85 -> 30824.56 | F36: ='Patient Acquisition'!F85 -> 33996.04 | G36: ='Patient Acquisition'!G85 -> 37912.101 | H36: ='Patient Acquisition'!H85 -> 41001.704 | I36: ='Patient Acquisition'!I85 -> 41001.704 | ... K36: ='Patient Acquisition'!K85 -> 41001.704
A37: Total Staff Capacity | B37: =Assumptions!C190 -> 30310.8 | C37: =Assumptions!D190 -> 31668 | D37: =Assumptions!E190 -> 38001.6 | E37: =Assumptions!F190 -> 41620.8 | F37: =Assumptions!G190 -> 44335.2 | G37: =Assumptions!H190 -> 49311.6 | H37: =Assumptions!I190 -> 50668.8 | I37: =Assumptions!J190 -> 50668.8 | ... K37: =Assumptions!L190 -> 52026
A38: Total Room Capacity | B38: =Assumptions!$D$44 -> 55640 | C38: =Assumptions!$D$44 -> 55640 | D38: =Assumptions!$D$44 -> 55640 | E38: =Assumptions!$D$44 -> 55640 | F38: =Assumptions!$D$44 -> 55640 | G38: =Assumptions!$D$44 -> 55640 | H38: =Assumptions!$D$44 -> 55640 | I38: =Assumptions!$D$44 -> 55640 | ... K38: =Assumptions!$D$44 -> 55640
A39: STAFF Utilization | B39: =IF(B37>0,B36/(B37/Assumptions!$D$19),0) -> 0.36571642 | C39: =IF(C37>0,C36/(C37/Assumptions!$D$19),0) -> 0.55487143 | D39: =IF(D37>0,D36/(D37/Assumptions!$D$19),0) -> 0.63308333 | E39: =IF(E37>0,E36/(E37/Assumptions!$D$19),0) -> 0.64432609 | F39: =IF(F37>0,F36/(F37/Assumptions!$D$19),0) -> 0.66711224 | G39: =IF(G37>0,G36/(G37/Assumptions!$D$19),0) -> 0.66887969 | H39: =IF(H37>0,H36/(H37/Assumptions!$D$19),0) -> 0.70401278 | I39: =IF(I37>0,I36/(I37/Assumptions!$D$19),0) -> 0.70401278 | ... K39: =IF(K37>0,K36/(K37/Assumptions!$D$19),0) -> 0.68564723
A40: Target (mgmt input) | B40: =Assumptions!C159 -> 0.229 | C40: =Assumptions!D159 -> 0.363 | D40: =Assumptions!E159 -> 0.497 | E40: =Assumptions!F159 -> 0.554 | F40: =Assumptions!G159 -> 0.611 | G40: =Assumptions!H159 -> 0.688 | H40: =Assumptions!I159 -> 0.764 | I40: =Assumptions!J159 -> 0.764 | ... K40: =Assumptions!L159 -> 0.764
A41: Gap (Actual − Demand) | B41: =B42-B40 -> 0 | C41: =C42-C40 -> 0 | D41: =D42-D40 -> 0 | E41: =E42-E40 -> 0 | F41: =F42-F40 -> 0 | G41: =G42-G40 -> -0.0066178862 | H41: =H42-H40 -> -0.027089431 | I41: =I42-I40 -> -0.027089431 | ... K41: =K42-K40 -> -0.027089431
A42: ROOM Utilization | B42: =IF(B38>0,B36/B38,0) -> 0.229 | C42: =IF(C38>0,C36/C38,0) -> 0.363 | D42: =IF(D38>0,D36/D38,0) -> 0.497 | E42: =IF(E38>0,E36/E38,0) -> 0.554 | F42: =IF(F38>0,F36/F38,0) -> 0.611 | G42: =IF(G38>0,G36/G38,0) -> 0.68138211 | H42: =IF(H38>0,H36/H38,0) -> 0.73691057 | I42: =IF(I38>0,I36/I38,0) -> 0.73691057 | ... K42: =IF(K38>0,K36/K38,0) -> 0.73691057
A43: Binding Constraint | B43: =IF(B39>B42,"Staff","Room") -> Staff | C43: =IF(C39>C42,"Staff","Room") -> Staff | D43: =IF(D39>D42,"Staff","Room") -> Staff | E43: =IF(E39>E42,"Staff","Room") -> Staff | F43: =IF(F39>F42,"Staff","Room") -> Staff | G43: =IF(G39>G42,"Staff","Room") -> Room | H43: =IF(H39>H42,"Staff","Room") -> Room | I43: =IF(I39>I42,"Staff","Room") -> Room | ... K43: =IF(K39>K42,"Staff","Room") -> Room
A44: Spare Capacity (slots/year) | B44: =MIN(B37,B38)-B36 -> 17569.24 | C44: =MIN(C37,C38)-C36 -> 11470.68 | D44: =MIN(D37,D38)-D36 -> 10348.52 | E44: =MIN(E37,E38)-E36 -> 10796.24 | F44: =MIN(F37,F38)-F36 -> 10339.16 | G44: =MIN(G37,G38)-G36 -> 11399.499 | H44: =MIN(H37,H38)-H36 -> 9667.0959 | I44: =MIN(I37,I38)-I36 -> 9667.0959 | ... K44: =MIN(K37,K38)-K36 -> 11024.296
A45: Revenue per Visit (AED) | B45: =IF(B36>0,Revenue!B13/B36,0) -> 600.02072 | C45: =IF(C36>0,Revenue!C13/C36,0) -> 620.2209 | D45: =IF(D36>0,Revenue!D13/D36,0) -> 645.62568 | E45: =IF(E36>0,Revenue!E13/E36,0) -> 672.78228 | F45: =IF(F36>0,Revenue!F13/F36,0) -> 698.30109 | G45: =IF(G36>0,Revenue!G13/G36,0) -> 729.31588 | H45: =IF(H36>0,Revenue!H13/H36,0) -> 761.43734 | I45: =IF(I36>0,Revenue!I13/I36,0) -> 791.89483 | ... K45: =IF(K36>0,Revenue!K13/K36,0) -> 856.51345
A46: VISITS PER SPECIALIST (annual) | B46: Year 1 | C46: Year 2 | D46: Year 3 | E46: Year 4 | F46: Year 5 | G46: Year 6 | H46: Year 7 | I46: Year 8 | J46: Year 9 | K46: Year 10
A47: Physio Clinic | B47: =IF(Assumptions!C179>0,B7/Assumptions!C179,0) -> 805.69937 | C47: =IF(Assumptions!D179>0,C7/Assumptions!D179,0) -> 1277.1566 | D47: =IF(Assumptions!E179>0,D7/Assumptions!E179,0) -> 1311.4604 | E47: =IF(Assumptions!F179>0,E7/Assumptions!F179,0) -> 1349.4179 | F47: =IF(Assumptions!G179>0,F7/Assumptions!G179,0) -> 1289.8227 | G47: =IF(Assumptions!H179>0,G7/Assumptions!H179,0) -> 1281.5028 | H47: =IF(Assumptions!I179>0,H7/Assumptions!I179,0) -> 1344.0051 | I47: =IF(Assumptions!J179>0,I7/Assumptions!J179,0) -> 1344.0051 | ... K47: =IF(Assumptions!L179>0,K7/Assumptions!L179,0) -> 1273.268
...

Sheet Sales Plan
A1: SALES PLAN — Dual Validation
A3: Revenue Stream | B3: Y1 | C3: Y2 | D3: Y3 | E3: Y4 | F3: Y5 | G3: Y6 | H3: Y7 | I3: Y8 | J3: Y9 | K3: Y10
A4: 1. BOTTOM-UP REVENUE (from Price List × Qty × Inflation)
A5: Physio Clinic | B5: =Revenue!B8 -> 4349400 | C5: =Revenue!C8 -> 7153536 | D5: =Revenue!D8 -> 10192566 | E5: =Revenue!E8 -> 11819846 | F5: =Revenue!F8 -> 13554683 | G5: =Revenue!G8 -> 15884620 | H5: =Revenue!H8 -> 18339787 | I5: =Revenue!I8 -> 19073378 | ... K5: =Revenue!K8 -> 20629766
A6: Dental Clinic | B6: =Revenue!B9 -> 1173000 | C6: =Revenue!C9 -> 1888224 | D6: =Revenue!D9 -> 2680204.8 | E6: =Revenue!E9 -> 3152543.8 | F6: =Revenue!F9 -> 3573450 | G6: =Revenue!G9 -> 4214242.3 | H6: =Revenue!H9 -> 4690284.5 | I6: =Revenue!I9 -> 4877895.9 | ... K6: =Revenue!K9 -> 5275932.2
A7: Polyclinic | B7: =Revenue!B10 -> 816000 | C7: =Revenue!C10 -> 1334112 | D7: =Revenue!D10 -> 1914432 | E7: =Revenue!E10 -> 2212382.5 | F7: =Revenue!F10 -> 2536721.3 | G7: =Revenue!G10 -> 2978366.3 | H7: =Revenue!H10 -> 3434581.9 | I7: =Revenue!I10 -> 3571965.2 | ... K7: =Revenue!K10 -> 3863437.6
A8: Cosmetology | B8: =Revenue!B11 -> 1306800 | C8: =Revenue!C11 -> 2150928 | D8: =Revenue!D11 -> 3066336 | E8: =Revenue!E11 -> 3553445.4 | F8: =Revenue!F11 -> 4074617.4 | G8: =Revenue!G11 -> 4572668.3 | H8: =Revenue!H11 -> 4755575 | I8: =Revenue!I11 -> 4945798 | ... K8: =Revenue!K11 -> 5349375.1
A9: Wellness Packages | B9: =Revenue!B12 -> 0 | C9: =Revenue!C12 -> 0 | D9: =Revenue!D12 -> 0 | E9: =Revenue!E12 -> 0 | F9: =Revenue!F12 -> 0 | G9: =Revenue!G12 -> 0 | H9: =Revenue!H12 -> 0 | I9: =Revenue!I12 -> 0 | ... K9: =Revenue!K12 -> 0
A10: TOTAL BOTTOM-UP | B10: =SUM(B5:B9) -> 7645200 | C10: =SUM(C5:C9) -> 12526800 | D10: =SUM(D5:D9) -> 17853539 | E10: =SUM(E5:E9) -> 20738218 | F10: =SUM(F5:F9) -> 23739472 | G10: =SUM(G5:G9) -> 27649897 | H10: =SUM(H5:H9) -> 31220228 | I10: =SUM(I5:I9) -> 32469038 | ... K10: =SUM(K5:K9) -> 35118511
A12: 2. TOP-DOWN TARGETS (Revenue at Full Capacity)
A13: Physio Clinic | B13: =IFERROR(B5/Assumptions!B242,0) -> 14498000 | C13: =IFERROR(C5/Assumptions!C242,0) -> 10735553 | D13: =IFERROR(D5/Assumptions!D242,0) -> 11672413 | E13: =IFERROR(E5/Assumptions!E242,0) -> 14571921 | F13: =IFERROR(F5/Assumptions!F242,0) -> 16594779 | G13: =IFERROR(G5/Assumptions!G242,0) -> 18397125 | H13: =IFERROR(H5/Assumptions!H242,0) -> 21274673 | I13: =IFERROR(I5/Assumptions!I242,0) -> 22734623 | ... K13: =IFERROR(K5/Assumptions!K242,0) -> 24589769
A14: Dental Clinic | B14: =IFERROR(B6/Assumptions!B242,0) -> 3910000 | C14: =IFERROR(C6/Assumptions!C242,0) -> 2833721.5 | D14: =IFERROR(D6/Assumptions!D242,0) -> 3069340.8 | E14: =IFERROR(E6/Assumptions!E242,0) -> 3886566.8 | F14: =IFERROR(F6/Assumptions!F242,0) -> 4374916.8 | G14: =IFERROR(G6/Assumptions!G242,0) -> 4880818 | H14: =IFERROR(H6/Assumptions!H242,0) -> 5440863.2 | I14: =IFERROR(I6/Assumptions!I242,0) -> 5814236.2 | ... K14: =IFERROR(K6/Assumptions!K242,0) -> 6288677.8
A15: Polyclinic | B15: =IFERROR(B7/Assumptions!B242,0) -> 2720000 | C15: =IFERROR(C7/Assumptions!C242,0) -> 2002146.9 | D15: =IFERROR(D7/Assumptions!D242,0) -> 2192386.3 | E15: =IFERROR(E7/Assumptions!E242,0) -> 2727502.9 | F15: =IFERROR(F7/Assumptions!F242,0) -> 3105666.7 | G15: =IFERROR(G7/Assumptions!G242,0) -> 3449460.9 | H15: =IFERROR(H7/Assumptions!H242,0) -> 3984212.5 | I15: =IFERROR(I7/Assumptions!I242,0) -> 4257624.5 | ... K15: =IFERROR(K7/Assumptions!K242,0) -> 4605046.7
A16: Cosmetology | B16: =IFERROR(B8/Assumptions!B242,0) -> 4356000 | C16: =IFERROR(C8/Assumptions!C242,0) -> 3227970.3 | D16: =IFERROR(D8/Assumptions!D242,0) -> 3511533.9 | E16: =IFERROR(E8/Assumptions!E242,0) -> 4380812.2 | F16: =IFERROR(F8/Assumptions!F242,0) -> 4988487.9 | G16: =IFERROR(G8/Assumptions!G242,0) -> 5295937 | H16: =IFERROR(H8/Assumptions!H242,0) -> 5516602 | I16: =IFERROR(I8/Assumptions!I242,0) -> 5895172.4 | ... K16: =IFERROR(K8/Assumptions!K242,0) -> 6376218.5
A17: Wellness Packages | B17: =IFERROR(B9/Assumptions!B242,0) -> 0 | C17: =IFERROR(C9/Assumptions!C242,0) -> 0 | D17: =IFERROR(D9/Assumptions!D242,0) -> 0 | E17: =IFERROR(E9/Assumptions!E242,0) -> 0 | F17: =IFERROR(F9/Assumptions!F242,0) -> 0 | G17: =IFERROR(G9/Assumptions!G242,0) -> 0 | H17: =IFERROR(H9/Assumptions!H242,0) -> 0 | I17: =IFERROR(I9/Assumptions!I242,0) -> 0 | ... K17: =IFERROR(K9/Assumptions!K242,0) -> 0
A18: TOTAL TARGET | B18: =SUM(B13:B17) -> 25484000 | C18: =SUM(C13:C17) -> 18799392 | D18: =SUM(D13:D17) -> 20445674 | E18: =SUM(E13:E17) -> 25566803 | F18: =SUM(F13:F17) -> 29063850 | G18: =SUM(G13:G17) -> 32023341 | H18: =SUM(H13:H17) -> 36216351 | I18: =SUM(I13:I17) -> 38701657 | ... K18: =SUM(K13:K17) -> 41859712
A19: Full capacity = Bottom-Up ÷ Utilization Factor (from cohort model)
A20: 3. GAP ANALYSIS (Target − Bottom-Up)
A21: Total Gap (AED) | B21: =B18-B10 -> 17838800 | C21: =C18-C10 -> 6272591.7 | D21: =D18-D10 -> 2592135.5 | E21: =E18-E10 -> 4828585.3 | F21: =F18-F10 -> 5324378.2 | G21: =G18-G10 -> 4373443.3 | H21: =H18-H10 -> 4996122.6 | I21: =I18-I10 -> 6232619 | ... K21: =K18-K10 -> 6741200.7
A22: Gap (%) | B22: =IF(B10<>0,(B18-B10)/B10,0) -> 2.3333333 | C22: =IF(C10<>0,(C18-C10)/C10,0) -> 0.50073376 | D22: =IF(D10<>0,(D18-D10)/D10,0) -> 0.14518889 | E22: =IF(E10<>0,(E18-E10)/E10,0) -> 0.23283512 | F22: =IF(F10<>0,(F18-F10)/F10,0) -> 0.22428377 | G22: =IF(G10<>0,(G18-G10)/G10,0) -> 0.15817214 | H22: =IF(H10<>0,(H18-H10)/H10,0) -> 0.16002838 | I22: =IF(I10<>0,(I18-I10)/I10,0) -> 0.19195577 | ... K22: =IF(K10<>0,(K18-K10)/K10,0) -> 0.19195577
A23: GAP Interpretation: positive = marketing needed to reach target
A24: 4. REVENUE MIX (% of Total)
A25: Physio Clinic | B25: =IF(B10<>0,B5/B10,0) -> 0.56890598 | C25: =IF(C10<>0,C5/C10,0) -> 0.57105853 | D25: =IF(D10<>0,D5/D10,0) -> 0.57089891 | E25: =IF(E10<>0,E5/E10,0) -> 0.56995476 | F25: =IF(F10<>0,F5/F10,0) -> 0.57097661 | G25: =IF(G10<>0,G5/G10,0) -> 0.57449112 | H25: =IF(H10<>0,H5/H10,0) -> 0.58743282 | I25: =IF(I10<>0,I5/I10,0) -> 0.58743282 | ... K25: =IF(K10<>0,K5/K10,0) -> 0.58743282
A26: Dental Clinic | B26: =IF(B10<>0,B6/B10,0) -> 0.1534296 | C26: =IF(C10<>0,C6/C10,0) -> 0.15073474 | D26: =IF(D10<>0,D6/D10,0) -> 0.15012177 | E26: =IF(E10<>0,E6/E10,0) -> 0.15201614 | F26: =IF(F10<>0,F6/F10,0) -> 0.15052778 | G26: =IF(G10<>0,G6/G10,0) -> 0.15241439 | H26: =IF(H10<>0,H6/H10,0) -> 0.15023223 | I26: =IF(I10<>0,I6/I10,0) -> 0.15023223 | ... K26: =IF(K10<>0,K6/K10,0) -> 0.15023223
A27: Polyclinic | B27: =IF(B10<>0,B7/B10,0) -> 0.10673364 | C27: =IF(C10<>0,C7/C10,0) -> 0.10650062 | D27: =IF(D10<>0,D7/D10,0) -> 0.10722984 | E27: =IF(E10<>0,E7/E10,0) -> 0.10668142 | F27: =IF(F10<>0,F7/F10,0) -> 0.10685669 | G27: =IF(G10<>0,G7/G10,0) -> 0.10771708 | H27: =IF(H10<>0,H7/H10,0) -> 0.11001143 | I27: =IF(I10<>0,I7/I10,0) -> 0.11001143 | ... K27: =IF(K10<>0,K7/K10,0) -> 0.11001143
A28: Cosmetology | B28: =IF(B10<>0,B8/B10,0) -> 0.17093078 | C28: =IF(C10<>0,C8/C10,0) -> 0.1717061 | D28: =IF(D10<>0,D8/D10,0) -> 0.17174948 | E28: =IF(E10<>0,E8/E10,0) -> 0.17134767 | F28: =IF(F10<>0,F8/F10,0) -> 0.17163892 | G28: =IF(G10<>0,G8/G10,0) -> 0.16537741 | H28: =IF(H10<>0,H8/H10,0) -> 0.15232352 | I28: =IF(I10<>0,I8/I10,0) -> 0.15232352 | ... K28: =IF(K10<>0,K8/K10,0) -> 0.15232352
A29: Wellness Packages | B29: =IF(B10<>0,B9/B10,0) -> 0 | C29: =IF(C10<>0,C9/C10,0) -> 0 | D29: =IF(D10<>0,D9/D10,0) -> 0 | E29: =IF(E10<>0,E9/E10,0) -> 0 | F29: =IF(F10<>0,F9/F10,0) -> 0 | G29: =IF(G10<>0,G9/G10,0) -> 0 | H29: =IF(H10<>0,H9/H10,0) -> 0 | I29: =IF(I10<>0,I9/I10,0) -> 0 | ... K29: =IF(K10<>0,K9/K10,0) -> 0
A31: 5. REVENUE PER SQM
A32: Total Revenue / sqm | B32: =B10/Assumptions!$D$9 -> 12330.968 | C32: =C10/Assumptions!$D$9 -> 20204.516 | D32: =D10/Assumptions!$D$9 -> 28796.03 | E32: =E10/Assumptions!$D$9 -> 33448.738 | F32: =F10/Assumptions!$D$9 -> 38289.471 | G32: =G10/Assumptions!$D$9 -> 44596.608 | H32: =H10/Assumptions!$D$9 -> 50355.207 | I32: =I10/Assumptions!$D$9 -> 52369.415 | ... K32: =K10/Assumptions!$D$9 -> 56642.76
A34: 6. PATIENT ACQUISITION EFFICIENCY
